[2025-04-14T10:17:43.002+0000] {local_task_job_runner.py:123} INFO - ::group::Pre task execution logs
[2025-04-14T10:17:43.021+0000] {taskinstance.py:2612} INFO - Dependencies all met for dep_context=non-requeueable deps ti=<TaskInstance: extract_raw_data_pipeline.extract_raw_data scheduled__2025-04-13T07:59:00+00:00 [queued]>
[2025-04-14T10:17:43.030+0000] {taskinstance.py:2612} INFO - Dependencies all met for dep_context=requeueable deps ti=<TaskInstance: extract_raw_data_pipeline.extract_raw_data scheduled__2025-04-13T07:59:00+00:00 [queued]>
[2025-04-14T10:17:43.030+0000] {taskinstance.py:2865} INFO - Starting attempt 1 of 1
[2025-04-14T10:17:43.044+0000] {taskinstance.py:2888} INFO - Executing <Task(PythonOperator): extract_raw_data> on 2025-04-13 07:59:00+00:00
[2025-04-14T10:17:43.050+0000] {warnings.py:112} WARNING - /home/***/.local/lib/python3.12/site-packages/***/task/task_runner/standard_task_runner.py:70: DeprecationWarning: This process (pid=59) is multi-threaded, use of fork() may lead to deadlocks in the child.
  pid = os.fork()

[2025-04-14T10:17:43.053+0000] {standard_task_runner.py:104} INFO - Running: ['***', 'tasks', 'run', 'extract_raw_data_pipeline', 'extract_raw_data', 'scheduled__2025-04-13T07:59:00+00:00', '--job-id', '25', '--raw', '--subdir', 'DAGS_FOLDER/lead_data_pipeline.py', '--cfg-path', '/tmp/tmp6i51aose']
[2025-04-14T10:17:43.054+0000] {standard_task_runner.py:72} INFO - Started process 64 to run task
[2025-04-14T10:17:43.055+0000] {standard_task_runner.py:105} INFO - Job 25: Subtask extract_raw_data
[2025-04-14T10:17:43.116+0000] {task_command.py:467} INFO - Running <TaskInstance: extract_raw_data_pipeline.extract_raw_data scheduled__2025-04-13T07:59:00+00:00 [running]> on host 9276b9d03819
[2025-04-14T10:17:43.215+0000] {taskinstance.py:3131} INFO - Exporting env vars: AIRFLOW_CTX_DAG_OWNER='***' AIRFLOW_CTX_DAG_ID='extract_raw_data_pipeline' AIRFLOW_CTX_TASK_ID='extract_raw_data' AIRFLOW_CTX_EXECUTION_DATE='2025-04-13T07:59:00+00:00' AIRFLOW_CTX_TRY_NUMBER='1' AIRFLOW_CTX_DAG_RUN_ID='scheduled__2025-04-13T07:59:00+00:00'
[2025-04-14T10:17:43.216+0000] {taskinstance.py:731} INFO - ::endgroup::
[2025-04-14T10:17:43.251+0000] {lead_data_pipeline.py:144} INFO - Started batch processing for 2025-04-14.
[2025-04-14T10:17:43.252+0000] {lead_data_pipeline.py:34} INFO - Created synthetic data for RO country code.
[2025-04-14T10:17:43.328+0000] {lead_data_pipeline.py:101} INFO - Written 85 records to the CSV file.
[2025-04-14T10:17:43.391+0000] {taskinstance.py:3310} ERROR - Task failed with exception
Traceback (most recent call last):
  File "/home/airflow/.local/lib/python3.12/site-packages/airflow/models/taskinstance.py", line 767, in _execute_task
    result = _execute_callable(context=context, **execute_callable_kwargs)
             ^^^^^^^^^^^^^^^^^^^^^^^^^^^^^^^^^^^^^^^^^^^^^^^^^^^^^^^^^^^^^
  File "/home/airflow/.local/lib/python3.12/site-packages/airflow/models/taskinstance.py", line 733, in _execute_callable
    return ExecutionCallableRunner(
           ^^^^^^^^^^^^^^^^^^^^^^^^
  File "/home/airflow/.local/lib/python3.12/site-packages/airflow/utils/operator_helpers.py", line 252, in run
    return self.func(*args, **kwargs)
           ^^^^^^^^^^^^^^^^^^^^^^^^^^
  File "/home/airflow/.local/lib/python3.12/site-packages/airflow/models/baseoperator.py", line 406, in wrapper
    return func(self, *args, **kwargs)
           ^^^^^^^^^^^^^^^^^^^^^^^^^^^
  File "/home/airflow/.local/lib/python3.12/site-packages/airflow/operators/python.py", line 238, in execute
    return_value = self.execute_callable()
                   ^^^^^^^^^^^^^^^^^^^^^^^
  File "/home/airflow/.local/lib/python3.12/site-packages/airflow/operators/python.py", line 256, in execute_callable
    return runner.run(*self.op_args, **self.op_kwargs)
           ^^^^^^^^^^^^^^^^^^^^^^^^^^^^^^^^^^^^^^^^^^^
  File "/home/airflow/.local/lib/python3.12/site-packages/airflow/utils/operator_helpers.py", line 252, in run
    return self.func(*args, **kwargs)
           ^^^^^^^^^^^^^^^^^^^^^^^^^^
  File "/opt/airflow/dags/lead_data_pipeline.py", line 148, in save_raw_data
    _add_id()
  File "/opt/airflow/dags/lead_data_pipeline.py", line 109, in _add_id
    df = pl.read_csv("/opt/airflow/data/raw_data.csv")
         ^^^^^^^^^^^^^^^^^^^^^^^^^^^^^^^^^^^^^^^^^^^^^
  File "/home/airflow/.local/lib/python3.12/site-packages/polars/_utils/deprecation.py", line 91, in wrapper
    return function(*args, **kwargs)
           ^^^^^^^^^^^^^^^^^^^^^^^^^
  File "/home/airflow/.local/lib/python3.12/site-packages/polars/_utils/deprecation.py", line 91, in wrapper
    return function(*args, **kwargs)
           ^^^^^^^^^^^^^^^^^^^^^^^^^
  File "/home/airflow/.local/lib/python3.12/site-packages/polars/_utils/deprecation.py", line 91, in wrapper
    return function(*args, **kwargs)
           ^^^^^^^^^^^^^^^^^^^^^^^^^
  File "/home/airflow/.local/lib/python3.12/site-packages/polars/io/csv/functions.py", line 500, in read_csv
    df = _read_csv_impl(
         ^^^^^^^^^^^^^^^
  File "/home/airflow/.local/lib/python3.12/site-packages/polars/io/csv/functions.py", line 646, in _read_csv_impl
    pydf = PyDataFrame.read_csv(
           ^^^^^^^^^^^^^^^^^^^^^
polars.exceptions.ComputeError: could not parse `personal_number` as dtype `i64` at column 'personal_number' (column number 4)

The current offset in the file is 27559796 bytes.

You might want to try:
- increasing `infer_schema_length` (e.g. `infer_schema_length=10000`),
- specifying correct dtype with the `dtypes` argument
- setting `ignore_errors` to `True`,
- adding `personal_number` to the `null_values` list.

Original error: ```remaining bytes non-empty```
[2025-04-14T10:17:43.404+0000] {taskinstance.py:1225} INFO - Marking task as FAILED. dag_id=extract_raw_data_pipeline, task_id=extract_raw_data, run_id=scheduled__2025-04-13T07:59:00+00:00, execution_date=20250413T075900, start_date=20250414T101743, end_date=20250414T101743
[2025-04-14T10:17:43.418+0000] {taskinstance.py:340} INFO - ::group::Post task execution logs
[2025-04-14T10:17:43.419+0000] {standard_task_runner.py:124} ERROR - Failed to execute job 25 for task extract_raw_data (could not parse `personal_number` as dtype `i64` at column 'personal_number' (column number 4)

The current offset in the file is 27559796 bytes.

You might want to try:
- increasing `infer_schema_length` (e.g. `infer_schema_length=10000`),
- specifying correct dtype with the `dtypes` argument
- setting `ignore_errors` to `True`,
- adding `personal_number` to the `null_values` list.

Original error: ```remaining bytes non-empty```; 64)
Traceback (most recent call last):
  File "/home/airflow/.local/lib/python3.12/site-packages/airflow/task/task_runner/standard_task_runner.py", line 117, in _start_by_fork
    ret = args.func(args, dag=self.dag)
          ^^^^^^^^^^^^^^^^^^^^^^^^^^^^^
  File "/home/airflow/.local/lib/python3.12/site-packages/airflow/cli/cli_config.py", line 49, in command
    return func(*args, **kwargs)
           ^^^^^^^^^^^^^^^^^^^^^
  File "/home/airflow/.local/lib/python3.12/site-packages/airflow/utils/cli.py", line 115, in wrapper
    return f(*args, **kwargs)
           ^^^^^^^^^^^^^^^^^^
  File "/home/airflow/.local/lib/python3.12/site-packages/airflow/cli/commands/task_command.py", line 483, in task_run
    task_return_code = _run_task_by_selected_method(args, _dag, ti)
                       ^^^^^^^^^^^^^^^^^^^^^^^^^^^^^^^^^^^^^^^^^^^^
  File "/home/airflow/.local/lib/python3.12/site-packages/airflow/cli/commands/task_command.py", line 256, in _run_task_by_selected_method
    return _run_raw_task(args, ti)
           ^^^^^^^^^^^^^^^^^^^^^^^
  File "/home/airflow/.local/lib/python3.12/site-packages/airflow/cli/commands/task_command.py", line 341, in _run_raw_task
    return ti._run_raw_task(
           ^^^^^^^^^^^^^^^^^
  File "/home/airflow/.local/lib/python3.12/site-packages/airflow/utils/session.py", line 97, in wrapper
    return func(*args, session=session, **kwargs)
           ^^^^^^^^^^^^^^^^^^^^^^^^^^^^^^^^^^^^^^
  File "/home/airflow/.local/lib/python3.12/site-packages/airflow/models/taskinstance.py", line 3004, in _run_raw_task
    return _run_raw_task(
           ^^^^^^^^^^^^^^
  File "/home/airflow/.local/lib/python3.12/site-packages/airflow/models/taskinstance.py", line 273, in _run_raw_task
    TaskInstance._execute_task_with_callbacks(
  File "/home/airflow/.local/lib/python3.12/site-packages/airflow/models/taskinstance.py", line 3158, in _execute_task_with_callbacks
    result = self._execute_task(context, task_orig)
             ^^^^^^^^^^^^^^^^^^^^^^^^^^^^^^^^^^^^^^
  File "/home/airflow/.local/lib/python3.12/site-packages/airflow/models/taskinstance.py", line 3182, in _execute_task
    return _execute_task(self, context, task_orig)
           ^^^^^^^^^^^^^^^^^^^^^^^^^^^^^^^^^^^^^^^
  File "/home/airflow/.local/lib/python3.12/site-packages/airflow/models/taskinstance.py", line 767, in _execute_task
    result = _execute_callable(context=context, **execute_callable_kwargs)
             ^^^^^^^^^^^^^^^^^^^^^^^^^^^^^^^^^^^^^^^^^^^^^^^^^^^^^^^^^^^^^
  File "/home/airflow/.local/lib/python3.12/site-packages/airflow/models/taskinstance.py", line 733, in _execute_callable
    return ExecutionCallableRunner(
           ^^^^^^^^^^^^^^^^^^^^^^^^
  File "/home/airflow/.local/lib/python3.12/site-packages/airflow/utils/operator_helpers.py", line 252, in run
    return self.func(*args, **kwargs)
           ^^^^^^^^^^^^^^^^^^^^^^^^^^
  File "/home/airflow/.local/lib/python3.12/site-packages/airflow/models/baseoperator.py", line 406, in wrapper
    return func(self, *args, **kwargs)
           ^^^^^^^^^^^^^^^^^^^^^^^^^^^
  File "/home/airflow/.local/lib/python3.12/site-packages/airflow/operators/python.py", line 238, in execute
    return_value = self.execute_callable()
                   ^^^^^^^^^^^^^^^^^^^^^^^
  File "/home/airflow/.local/lib/python3.12/site-packages/airflow/operators/python.py", line 256, in execute_callable
    return runner.run(*self.op_args, **self.op_kwargs)
           ^^^^^^^^^^^^^^^^^^^^^^^^^^^^^^^^^^^^^^^^^^^
  File "/home/airflow/.local/lib/python3.12/site-packages/airflow/utils/operator_helpers.py", line 252, in run
    return self.func(*args, **kwargs)
           ^^^^^^^^^^^^^^^^^^^^^^^^^^
  File "/opt/airflow/dags/lead_data_pipeline.py", line 148, in save_raw_data
    _add_id()
  File "/opt/airflow/dags/lead_data_pipeline.py", line 109, in _add_id
    df = pl.read_csv("/opt/airflow/data/raw_data.csv")
         ^^^^^^^^^^^^^^^^^^^^^^^^^^^^^^^^^^^^^^^^^^^^^
  File "/home/airflow/.local/lib/python3.12/site-packages/polars/_utils/deprecation.py", line 91, in wrapper
    return function(*args, **kwargs)
           ^^^^^^^^^^^^^^^^^^^^^^^^^
  File "/home/airflow/.local/lib/python3.12/site-packages/polars/_utils/deprecation.py", line 91, in wrapper
    return function(*args, **kwargs)
           ^^^^^^^^^^^^^^^^^^^^^^^^^
  File "/home/airflow/.local/lib/python3.12/site-packages/polars/_utils/deprecation.py", line 91, in wrapper
    return function(*args, **kwargs)
           ^^^^^^^^^^^^^^^^^^^^^^^^^
  File "/home/airflow/.local/lib/python3.12/site-packages/polars/io/csv/functions.py", line 500, in read_csv
    df = _read_csv_impl(
         ^^^^^^^^^^^^^^^
  File "/home/airflow/.local/lib/python3.12/site-packages/polars/io/csv/functions.py", line 646, in _read_csv_impl
    pydf = PyDataFrame.read_csv(
           ^^^^^^^^^^^^^^^^^^^^^
polars.exceptions.ComputeError: could not parse `personal_number` as dtype `i64` at column 'personal_number' (column number 4)

The current offset in the file is 27559796 bytes.

You might want to try:
- increasing `infer_schema_length` (e.g. `infer_schema_length=10000`),
- specifying correct dtype with the `dtypes` argument
- setting `ignore_errors` to `True`,
- adding `personal_number` to the `null_values` list.

Original error: ```remaining bytes non-empty```
[2025-04-14T10:17:43.437+0000] {local_task_job_runner.py:266} INFO - Task exited with return code 1
[2025-04-14T10:17:43.460+0000] {taskinstance.py:3900} INFO - 0 downstream tasks scheduled from follow-on schedule check
[2025-04-14T10:17:43.464+0000] {local_task_job_runner.py:245} INFO - ::endgroup::
