[2025-04-16T12:00:55.510+0000] {local_task_job_runner.py:123} INFO - ::group::Pre task execution logs
[2025-04-16T12:00:55.538+0000] {taskinstance.py:2612} INFO - Dependencies all met for dep_context=non-requeueable deps ti=<TaskInstance: extract_raw_data_pipeline.run_dbt_trusted scheduled__2025-04-15T07:52:00+00:00 [queued]>
[2025-04-16T12:00:55.556+0000] {taskinstance.py:2612} INFO - Dependencies all met for dep_context=requeueable deps ti=<TaskInstance: extract_raw_data_pipeline.run_dbt_trusted scheduled__2025-04-15T07:52:00+00:00 [queued]>
[2025-04-16T12:00:55.557+0000] {taskinstance.py:2865} INFO - Starting attempt 1 of 1
[2025-04-16T12:00:55.716+0000] {taskinstance.py:2888} INFO - Executing <Task(BashOperator): run_dbt_trusted> on 2025-04-15 07:52:00+00:00
[2025-04-16T12:00:55.724+0000] {warnings.py:112} WARNING - /home/***/.local/lib/python3.12/site-packages/***/task/task_runner/standard_task_runner.py:70: DeprecationWarning: This process (pid=4503) is multi-threaded, use of fork() may lead to deadlocks in the child.
  pid = os.fork()

[2025-04-16T12:00:55.726+0000] {standard_task_runner.py:72} INFO - Started process 4505 to run task
[2025-04-16T12:00:55.727+0000] {standard_task_runner.py:104} INFO - Running: ['***', 'tasks', 'run', 'extract_raw_data_pipeline', 'run_dbt_trusted', 'scheduled__2025-04-15T07:52:00+00:00', '--job-id', '126', '--raw', '--subdir', 'DAGS_FOLDER/lead_data_pipeline.py', '--cfg-path', '/tmp/tmp7mkxwnzt']
[2025-04-16T12:00:55.728+0000] {standard_task_runner.py:105} INFO - Job 126: Subtask run_dbt_trusted
[2025-04-16T12:00:56.056+0000] {task_command.py:467} INFO - Running <TaskInstance: extract_raw_data_pipeline.run_dbt_trusted scheduled__2025-04-15T07:52:00+00:00 [running]> on host c0ac39583bd8
[2025-04-16T12:00:56.261+0000] {taskinstance.py:3131} INFO - Exporting env vars: AIRFLOW_CTX_DAG_OWNER='***' AIRFLOW_CTX_DAG_ID='extract_raw_data_pipeline' AIRFLOW_CTX_TASK_ID='run_dbt_trusted' AIRFLOW_CTX_EXECUTION_DATE='2025-04-15T07:52:00+00:00' AIRFLOW_CTX_TRY_NUMBER='1' AIRFLOW_CTX_DAG_RUN_ID='scheduled__2025-04-15T07:52:00+00:00'
[2025-04-16T12:00:56.262+0000] {taskinstance.py:731} INFO - ::endgroup::
[2025-04-16T12:00:56.280+0000] {subprocess.py:63} INFO - Tmp dir root location: /tmp
[2025-04-16T12:00:56.282+0000] {subprocess.py:75} INFO - Running command: ['/usr/bin/bash', '-c', 'set -x; cd /opt/***/dbt && dbt run --select tag:trusted']
[2025-04-16T12:00:56.301+0000] {subprocess.py:86} INFO - Output:
[2025-04-16T12:00:56.303+0000] {subprocess.py:93} INFO - + cd /opt/***/dbt
[2025-04-16T12:00:56.304+0000] {subprocess.py:93} INFO - + dbt run --select tag:trusted
[2025-04-16T12:00:59.188+0000] {subprocess.py:93} INFO - [0m12:00:59  Running with dbt=1.8.0
[2025-04-16T12:00:59.529+0000] {subprocess.py:93} INFO - [0m12:00:59  Registered adapter: postgres=1.8.2
[2025-04-16T12:01:00.054+0000] {subprocess.py:93} INFO - [0m12:01:00  Found 9 models, 10 sources, 428 macros
[2025-04-16T12:01:00.057+0000] {subprocess.py:93} INFO - [0m12:01:00
[2025-04-16T12:01:00.209+0000] {subprocess.py:93} INFO - [0m12:01:00  Concurrency: 1 threads (target='dev')
[2025-04-16T12:01:00.210+0000] {subprocess.py:93} INFO - [0m12:01:00
[2025-04-16T12:01:00.224+0000] {subprocess.py:93} INFO - [0m12:01:00  1 of 4 START sql table model lead_trusted.non_pii_data ......................... [RUN]
[2025-04-16T12:05:03.185+0000] {subprocess.py:93} INFO - [0m12:05:03  1 of 4 OK created sql table model lead_trusted.non_pii_data .................... [[32mSELECT 27812086[0m in 242.96s]
[2025-04-16T12:05:03.188+0000] {subprocess.py:93} INFO - [0m12:05:03  2 of 4 START sql table model lead_trusted.payment_data ......................... [RUN]
[2025-04-16T12:05:19.646+0000] {subprocess.py:93} INFO - [0m12:05:19  2 of 4 OK created sql table model lead_trusted.payment_data .................... [[32mSELECT 3977366[0m in 16.46s]
[2025-04-16T12:05:19.650+0000] {subprocess.py:93} INFO - [0m12:05:19  3 of 4 START sql table model lead_trusted.pii_data ............................. [RUN]
[2025-04-16T12:06:26.861+0000] {subprocess.py:93} INFO - [0m12:06:26  3 of 4 ERROR creating sql table model lead_trusted.pii_data .................... [[31mERROR[0m in 67.21s]
[2025-04-16T12:06:26.865+0000] {subprocess.py:93} INFO - [0m12:06:26  4 of 4 START sql table model lead_trusted.technical_data ....................... [RUN]
[2025-04-16T12:06:38.261+0000] {subprocess.py:93} INFO - [0m12:06:38  4 of 4 OK created sql table model lead_trusted.technical_data .................. [[32mSELECT 4184733[0m in 11.39s]
[2025-04-16T12:06:38.278+0000] {subprocess.py:93} INFO - [0m12:06:38
[2025-04-16T12:06:38.279+0000] {subprocess.py:93} INFO - [0m12:06:38  Finished running 4 table models in 0 hours 5 minutes and 38.22 seconds (338.22s).
[2025-04-16T12:06:38.340+0000] {subprocess.py:93} INFO - [0m12:06:38
[2025-04-16T12:06:38.341+0000] {subprocess.py:93} INFO - [0m12:06:38  [31mCompleted with 1 error and 0 warnings:[0m
[2025-04-16T12:06:38.342+0000] {subprocess.py:93} INFO - [0m12:06:38
[2025-04-16T12:06:38.343+0000] {subprocess.py:93} INFO - [0m12:06:38    Database Error in model trusted_pii_data (models/trusted_pii_data.sql)
[2025-04-16T12:06:38.343+0000] {subprocess.py:93} INFO -   could not resize shared memory segment "/PostgreSQL.1451177995" to 33554432 bytes: No space left on device
[2025-04-16T12:06:38.344+0000] {subprocess.py:93} INFO -   CONTEXT:  parallel worker
[2025-04-16T12:06:38.345+0000] {subprocess.py:93} INFO -   compiled code at target/run/dbt_lead_data/models/trusted_pii_data.sql
[2025-04-16T12:06:38.345+0000] {subprocess.py:93} INFO - [0m12:06:38
[2025-04-16T12:06:38.346+0000] {subprocess.py:93} INFO - [0m12:06:38  Done. PASS=3 WARN=0 ERROR=1 SKIP=0 TOTAL=4
[2025-04-16T12:06:39.226+0000] {subprocess.py:97} INFO - Command exited with return code 1
[2025-04-16T12:06:39.240+0000] {taskinstance.py:3310} ERROR - Task failed with exception
Traceback (most recent call last):
  File "/home/airflow/.local/lib/python3.12/site-packages/airflow/models/taskinstance.py", line 767, in _execute_task
    result = _execute_callable(context=context, **execute_callable_kwargs)
             ^^^^^^^^^^^^^^^^^^^^^^^^^^^^^^^^^^^^^^^^^^^^^^^^^^^^^^^^^^^^^
  File "/home/airflow/.local/lib/python3.12/site-packages/airflow/models/taskinstance.py", line 733, in _execute_callable
    return ExecutionCallableRunner(
           ^^^^^^^^^^^^^^^^^^^^^^^^
  File "/home/airflow/.local/lib/python3.12/site-packages/airflow/utils/operator_helpers.py", line 252, in run
    return self.func(*args, **kwargs)
           ^^^^^^^^^^^^^^^^^^^^^^^^^^
  File "/home/airflow/.local/lib/python3.12/site-packages/airflow/models/baseoperator.py", line 406, in wrapper
    return func(self, *args, **kwargs)
           ^^^^^^^^^^^^^^^^^^^^^^^^^^^
  File "/home/airflow/.local/lib/python3.12/site-packages/airflow/operators/bash.py", line 249, in execute
    raise AirflowException(
airflow.exceptions.AirflowException: Bash command failed. The command returned a non-zero exit code 1.
[2025-04-16T12:06:39.254+0000] {taskinstance.py:1225} INFO - Marking task as FAILED. dag_id=extract_raw_data_pipeline, task_id=run_dbt_trusted, run_id=scheduled__2025-04-15T07:52:00+00:00, execution_date=20250415T075200, start_date=20250416T120055, end_date=20250416T120639
[2025-04-16T12:06:39.413+0000] {taskinstance.py:340} INFO - ::group::Post task execution logs
[2025-04-16T12:06:39.414+0000] {standard_task_runner.py:124} ERROR - Failed to execute job 126 for task run_dbt_trusted (Bash command failed. The command returned a non-zero exit code 1.; 4505)
Traceback (most recent call last):
  File "/home/airflow/.local/lib/python3.12/site-packages/airflow/task/task_runner/standard_task_runner.py", line 117, in _start_by_fork
    ret = args.func(args, dag=self.dag)
          ^^^^^^^^^^^^^^^^^^^^^^^^^^^^^
  File "/home/airflow/.local/lib/python3.12/site-packages/airflow/cli/cli_config.py", line 49, in command
    return func(*args, **kwargs)
           ^^^^^^^^^^^^^^^^^^^^^
  File "/home/airflow/.local/lib/python3.12/site-packages/airflow/utils/cli.py", line 115, in wrapper
    return f(*args, **kwargs)
           ^^^^^^^^^^^^^^^^^^
  File "/home/airflow/.local/lib/python3.12/site-packages/airflow/cli/commands/task_command.py", line 483, in task_run
    task_return_code = _run_task_by_selected_method(args, _dag, ti)
                       ^^^^^^^^^^^^^^^^^^^^^^^^^^^^^^^^^^^^^^^^^^^^
  File "/home/airflow/.local/lib/python3.12/site-packages/airflow/cli/commands/task_command.py", line 256, in _run_task_by_selected_method
    return _run_raw_task(args, ti)
           ^^^^^^^^^^^^^^^^^^^^^^^
  File "/home/airflow/.local/lib/python3.12/site-packages/airflow/cli/commands/task_command.py", line 341, in _run_raw_task
    return ti._run_raw_task(
           ^^^^^^^^^^^^^^^^^
  File "/home/airflow/.local/lib/python3.12/site-packages/airflow/utils/session.py", line 97, in wrapper
    return func(*args, session=session, **kwargs)
           ^^^^^^^^^^^^^^^^^^^^^^^^^^^^^^^^^^^^^^
  File "/home/airflow/.local/lib/python3.12/site-packages/airflow/models/taskinstance.py", line 3004, in _run_raw_task
    return _run_raw_task(
           ^^^^^^^^^^^^^^
  File "/home/airflow/.local/lib/python3.12/site-packages/airflow/models/taskinstance.py", line 273, in _run_raw_task
    TaskInstance._execute_task_with_callbacks(
  File "/home/airflow/.local/lib/python3.12/site-packages/airflow/models/taskinstance.py", line 3158, in _execute_task_with_callbacks
    result = self._execute_task(context, task_orig)
             ^^^^^^^^^^^^^^^^^^^^^^^^^^^^^^^^^^^^^^
  File "/home/airflow/.local/lib/python3.12/site-packages/airflow/models/taskinstance.py", line 3182, in _execute_task
    return _execute_task(self, context, task_orig)
           ^^^^^^^^^^^^^^^^^^^^^^^^^^^^^^^^^^^^^^^
  File "/home/airflow/.local/lib/python3.12/site-packages/airflow/models/taskinstance.py", line 767, in _execute_task
    result = _execute_callable(context=context, **execute_callable_kwargs)
             ^^^^^^^^^^^^^^^^^^^^^^^^^^^^^^^^^^^^^^^^^^^^^^^^^^^^^^^^^^^^^
  File "/home/airflow/.local/lib/python3.12/site-packages/airflow/models/taskinstance.py", line 733, in _execute_callable
    return ExecutionCallableRunner(
           ^^^^^^^^^^^^^^^^^^^^^^^^
  File "/home/airflow/.local/lib/python3.12/site-packages/airflow/utils/operator_helpers.py", line 252, in run
    return self.func(*args, **kwargs)
           ^^^^^^^^^^^^^^^^^^^^^^^^^^
  File "/home/airflow/.local/lib/python3.12/site-packages/airflow/models/baseoperator.py", line 406, in wrapper
    return func(self, *args, **kwargs)
           ^^^^^^^^^^^^^^^^^^^^^^^^^^^
  File "/home/airflow/.local/lib/python3.12/site-packages/airflow/operators/bash.py", line 249, in execute
    raise AirflowException(
airflow.exceptions.AirflowException: Bash command failed. The command returned a non-zero exit code 1.
[2025-04-16T12:06:39.438+0000] {local_task_job_runner.py:266} INFO - Task exited with return code 1
[2025-04-16T12:06:39.453+0000] {taskinstance.py:3900} INFO - 0 downstream tasks scheduled from follow-on schedule check
[2025-04-16T12:06:39.454+0000] {local_task_job_runner.py:245} INFO - ::endgroup::
