[2025-04-17T07:09:27.696+0000] {local_task_job_runner.py:123} INFO - ::group::Pre task execution logs
[2025-04-17T07:09:27.713+0000] {taskinstance.py:2612} INFO - Dependencies all met for dep_context=non-requeueable deps ti=<TaskInstance: extract_raw_data_pipeline.run_dbt_trusted scheduled__2025-04-16T07:59:00+00:00 [queued]>
[2025-04-17T07:09:27.722+0000] {taskinstance.py:2612} INFO - Dependencies all met for dep_context=requeueable deps ti=<TaskInstance: extract_raw_data_pipeline.run_dbt_trusted scheduled__2025-04-16T07:59:00+00:00 [queued]>
[2025-04-17T07:09:27.722+0000] {taskinstance.py:2865} INFO - Starting attempt 1 of 1
[2025-04-17T07:09:27.742+0000] {taskinstance.py:2888} INFO - Executing <Task(BashOperator): run_dbt_trusted> on 2025-04-16 07:59:00+00:00
[2025-04-17T07:09:27.748+0000] {warnings.py:112} WARNING - /home/***/.local/lib/python3.12/site-packages/***/task/task_runner/standard_task_runner.py:70: DeprecationWarning: This process (pid=12197) is multi-threaded, use of fork() may lead to deadlocks in the child.
  pid = os.fork()

[2025-04-17T07:09:27.749+0000] {standard_task_runner.py:72} INFO - Started process 12201 to run task
[2025-04-17T07:09:27.750+0000] {standard_task_runner.py:104} INFO - Running: ['***', 'tasks', 'run', 'extract_raw_data_pipeline', 'run_dbt_trusted', 'scheduled__2025-04-16T07:59:00+00:00', '--job-id', '147', '--raw', '--subdir', 'DAGS_FOLDER/lead_data_pipeline.py', '--cfg-path', '/tmp/tmppwzn5bpd']
[2025-04-17T07:09:27.751+0000] {standard_task_runner.py:105} INFO - Job 147: Subtask run_dbt_trusted
[2025-04-17T07:09:27.805+0000] {task_command.py:467} INFO - Running <TaskInstance: extract_raw_data_pipeline.run_dbt_trusted scheduled__2025-04-16T07:59:00+00:00 [running]> on host c0ac39583bd8
[2025-04-17T07:09:27.907+0000] {taskinstance.py:3131} INFO - Exporting env vars: AIRFLOW_CTX_DAG_OWNER='***' AIRFLOW_CTX_DAG_ID='extract_raw_data_pipeline' AIRFLOW_CTX_TASK_ID='run_dbt_trusted' AIRFLOW_CTX_EXECUTION_DATE='2025-04-16T07:59:00+00:00' AIRFLOW_CTX_TRY_NUMBER='1' AIRFLOW_CTX_DAG_RUN_ID='scheduled__2025-04-16T07:59:00+00:00'
[2025-04-17T07:09:27.908+0000] {taskinstance.py:731} INFO - ::endgroup::
[2025-04-17T07:09:27.923+0000] {subprocess.py:63} INFO - Tmp dir root location: /tmp
[2025-04-17T07:09:27.924+0000] {subprocess.py:75} INFO - Running command: ['/usr/bin/bash', '-c', 'set -x; cd /opt/***/dbt && dbt run --select tag:trusted']
[2025-04-17T07:09:27.934+0000] {subprocess.py:86} INFO - Output:
[2025-04-17T07:09:27.937+0000] {subprocess.py:93} INFO - + cd /opt/***/dbt
[2025-04-17T07:09:27.937+0000] {subprocess.py:93} INFO - + dbt run --select tag:trusted
[2025-04-17T07:09:30.300+0000] {subprocess.py:93} INFO - [0m07:09:30  Running with dbt=1.8.0
[2025-04-17T07:09:32.109+0000] {subprocess.py:93} INFO - [0m07:09:32  Registered adapter: postgres=1.8.2
[2025-04-17T07:09:35.184+0000] {subprocess.py:93} INFO - [0m07:09:35  Found 9 models, 10 sources, 428 macros
[2025-04-17T07:09:35.215+0000] {subprocess.py:93} INFO - [0m07:09:35
[2025-04-17T07:09:35.977+0000] {subprocess.py:93} INFO - [0m07:09:35  Concurrency: 1 threads (target='dev')
[2025-04-17T07:09:35.982+0000] {subprocess.py:93} INFO - [0m07:09:35
[2025-04-17T07:09:36.095+0000] {subprocess.py:93} INFO - [0m07:09:36  1 of 4 START sql table model lead_trusted.non_pii_data ......................... [RUN]
[2025-04-17T07:16:01.808+0000] {job.py:229} INFO - Heartbeat recovered after 378.63 seconds
[2025-04-17T07:28:06.611+0000] {job.py:229} INFO - Heartbeat recovered after 678.14 seconds
[2025-04-17T07:30:05.190+0000] {subprocess.py:93} INFO - [0m07:30:05  1 of 4 OK created sql table model lead_trusted.non_pii_data .................... [[32mSELECT 28436739[0m in 1229.09s]
[2025-04-17T07:30:05.193+0000] {subprocess.py:93} INFO - [0m07:30:05  2 of 4 START sql table model lead_trusted.payment_data ......................... [RUN]
[2025-04-17T07:30:32.224+0000] {subprocess.py:93} INFO - [0m07:30:32  2 of 4 OK created sql table model lead_trusted.payment_data .................... [[32mSELECT 4811372[0m in 27.03s]
[2025-04-17T07:30:32.228+0000] {subprocess.py:93} INFO - [0m07:30:32  3 of 4 START sql table model lead_trusted.pii_data ............................. [RUN]
[2025-04-17T07:33:20.978+0000] {subprocess.py:93} INFO - [0m07:33:20  3 of 4 ERROR creating sql table model lead_trusted.pii_data .................... [[31mERROR[0m in 168.74s]
[2025-04-17T07:33:20.988+0000] {subprocess.py:93} INFO - [0m07:33:20  4 of 4 START sql table model lead_trusted.technical_data ....................... [RUN]
[2025-04-17T07:34:10.118+0000] {subprocess.py:93} INFO - [0m07:34:10  4 of 4 OK created sql table model lead_trusted.technical_data .................. [[32mSELECT 6711816[0m in 49.13s]
[2025-04-17T07:34:10.141+0000] {subprocess.py:93} INFO - [0m07:34:10
[2025-04-17T07:34:10.142+0000] {subprocess.py:93} INFO - [0m07:34:10  Finished running 4 table models in 0 hours 24 minutes and 34.92 seconds (1474.92s).
[2025-04-17T07:34:10.230+0000] {subprocess.py:93} INFO - [0m07:34:10
[2025-04-17T07:34:10.233+0000] {subprocess.py:93} INFO - [0m07:34:10  [31mCompleted with 1 error and 0 warnings:[0m
[2025-04-17T07:34:10.235+0000] {subprocess.py:93} INFO - [0m07:34:10
[2025-04-17T07:34:10.237+0000] {subprocess.py:93} INFO - [0m07:34:10    Database Error in model trusted_pii_data (models/trusted_pii_data.sql)
[2025-04-17T07:34:10.238+0000] {subprocess.py:93} INFO -   could not extend file "base/16384/17981.5": No space left on device
[2025-04-17T07:34:10.240+0000] {subprocess.py:93} INFO -   HINT:  Check free disk space.
[2025-04-17T07:34:10.241+0000] {subprocess.py:93} INFO -   compiled code at target/run/dbt_lead_data/models/trusted_pii_data.sql
[2025-04-17T07:34:10.242+0000] {subprocess.py:93} INFO - [0m07:34:10
[2025-04-17T07:34:10.244+0000] {subprocess.py:93} INFO - [0m07:34:10  Done. PASS=3 WARN=0 ERROR=1 SKIP=0 TOTAL=4
[2025-04-17T07:34:12.145+0000] {subprocess.py:97} INFO - Command exited with return code 1
[2025-04-17T07:34:12.163+0000] {taskinstance.py:3310} ERROR - Task failed with exception
Traceback (most recent call last):
  File "/home/airflow/.local/lib/python3.12/site-packages/airflow/models/taskinstance.py", line 767, in _execute_task
    result = _execute_callable(context=context, **execute_callable_kwargs)
             ^^^^^^^^^^^^^^^^^^^^^^^^^^^^^^^^^^^^^^^^^^^^^^^^^^^^^^^^^^^^^
  File "/home/airflow/.local/lib/python3.12/site-packages/airflow/models/taskinstance.py", line 733, in _execute_callable
    return ExecutionCallableRunner(
           ^^^^^^^^^^^^^^^^^^^^^^^^
  File "/home/airflow/.local/lib/python3.12/site-packages/airflow/utils/operator_helpers.py", line 252, in run
    return self.func(*args, **kwargs)
           ^^^^^^^^^^^^^^^^^^^^^^^^^^
  File "/home/airflow/.local/lib/python3.12/site-packages/airflow/models/baseoperator.py", line 406, in wrapper
    return func(self, *args, **kwargs)
           ^^^^^^^^^^^^^^^^^^^^^^^^^^^
  File "/home/airflow/.local/lib/python3.12/site-packages/airflow/operators/bash.py", line 249, in execute
    raise AirflowException(
airflow.exceptions.AirflowException: Bash command failed. The command returned a non-zero exit code 1.
[2025-04-17T07:34:12.189+0000] {taskinstance.py:1225} INFO - Marking task as FAILED. dag_id=extract_raw_data_pipeline, task_id=run_dbt_trusted, run_id=scheduled__2025-04-16T07:59:00+00:00, execution_date=20250416T075900, start_date=20250417T070927, end_date=20250417T073412
[2025-04-17T07:34:12.418+0000] {taskinstance.py:340} INFO - ::group::Post task execution logs
[2025-04-17T07:34:12.419+0000] {standard_task_runner.py:124} ERROR - Failed to execute job 147 for task run_dbt_trusted (Bash command failed. The command returned a non-zero exit code 1.; 12201)
Traceback (most recent call last):
  File "/home/airflow/.local/lib/python3.12/site-packages/airflow/task/task_runner/standard_task_runner.py", line 117, in _start_by_fork
    ret = args.func(args, dag=self.dag)
          ^^^^^^^^^^^^^^^^^^^^^^^^^^^^^
  File "/home/airflow/.local/lib/python3.12/site-packages/airflow/cli/cli_config.py", line 49, in command
    return func(*args, **kwargs)
           ^^^^^^^^^^^^^^^^^^^^^
  File "/home/airflow/.local/lib/python3.12/site-packages/airflow/utils/cli.py", line 115, in wrapper
    return f(*args, **kwargs)
           ^^^^^^^^^^^^^^^^^^
  File "/home/airflow/.local/lib/python3.12/site-packages/airflow/cli/commands/task_command.py", line 483, in task_run
    task_return_code = _run_task_by_selected_method(args, _dag, ti)
                       ^^^^^^^^^^^^^^^^^^^^^^^^^^^^^^^^^^^^^^^^^^^^
  File "/home/airflow/.local/lib/python3.12/site-packages/airflow/cli/commands/task_command.py", line 256, in _run_task_by_selected_method
    return _run_raw_task(args, ti)
           ^^^^^^^^^^^^^^^^^^^^^^^
  File "/home/airflow/.local/lib/python3.12/site-packages/airflow/cli/commands/task_command.py", line 341, in _run_raw_task
    return ti._run_raw_task(
           ^^^^^^^^^^^^^^^^^
  File "/home/airflow/.local/lib/python3.12/site-packages/airflow/utils/session.py", line 97, in wrapper
    return func(*args, session=session, **kwargs)
           ^^^^^^^^^^^^^^^^^^^^^^^^^^^^^^^^^^^^^^
  File "/home/airflow/.local/lib/python3.12/site-packages/airflow/models/taskinstance.py", line 3004, in _run_raw_task
    return _run_raw_task(
           ^^^^^^^^^^^^^^
  File "/home/airflow/.local/lib/python3.12/site-packages/airflow/models/taskinstance.py", line 273, in _run_raw_task
    TaskInstance._execute_task_with_callbacks(
  File "/home/airflow/.local/lib/python3.12/site-packages/airflow/models/taskinstance.py", line 3158, in _execute_task_with_callbacks
    result = self._execute_task(context, task_orig)
             ^^^^^^^^^^^^^^^^^^^^^^^^^^^^^^^^^^^^^^
  File "/home/airflow/.local/lib/python3.12/site-packages/airflow/models/taskinstance.py", line 3182, in _execute_task
    return _execute_task(self, context, task_orig)
           ^^^^^^^^^^^^^^^^^^^^^^^^^^^^^^^^^^^^^^^
  File "/home/airflow/.local/lib/python3.12/site-packages/airflow/models/taskinstance.py", line 767, in _execute_task
    result = _execute_callable(context=context, **execute_callable_kwargs)
             ^^^^^^^^^^^^^^^^^^^^^^^^^^^^^^^^^^^^^^^^^^^^^^^^^^^^^^^^^^^^^
  File "/home/airflow/.local/lib/python3.12/site-packages/airflow/models/taskinstance.py", line 733, in _execute_callable
    return ExecutionCallableRunner(
           ^^^^^^^^^^^^^^^^^^^^^^^^
  File "/home/airflow/.local/lib/python3.12/site-packages/airflow/utils/operator_helpers.py", line 252, in run
    return self.func(*args, **kwargs)
           ^^^^^^^^^^^^^^^^^^^^^^^^^^
  File "/home/airflow/.local/lib/python3.12/site-packages/airflow/models/baseoperator.py", line 406, in wrapper
    return func(self, *args, **kwargs)
           ^^^^^^^^^^^^^^^^^^^^^^^^^^^
  File "/home/airflow/.local/lib/python3.12/site-packages/airflow/operators/bash.py", line 249, in execute
    raise AirflowException(
airflow.exceptions.AirflowException: Bash command failed. The command returned a non-zero exit code 1.
[2025-04-17T07:34:12.458+0000] {local_task_job_runner.py:266} INFO - Task exited with return code 1
[2025-04-17T07:34:12.472+0000] {local_task_job_runner.py:245} INFO - ::endgroup::
